<!--
    使用 xacro 优化 URDF 版的小车底盘实现：
-->
<robot name="my_base" xmlns:xacro="http://www.ros.org/wiki/xacro">
    <!-- 封装变量、常量 -->
    <xacro:property name="PI" value="3.1415926"/>
    
    <!-- 底盘属性 -->
    <xacro:property name="base_footprint_radius" value="0.001" />
    <xacro:property name="base_link_radius" value="0.25" />
    <xacro:property name="base_link_length" value="0.9" />
    <xacro:property name="earth_space" value="0.05" />
    <xacro:property name="base_link_m" value="5.0" />

    <!-- 底盘 -->
    <link name="base_footprint">
      <visual>
        <geometry>
          <sphere radius="${base_footprint_radius}" />
        </geometry>
      </visual>
    </link>

    <link name="base_link">
      <visual>
        <geometry>
          <!-- 使用DAE模型作为视觉 -->
          <mesh filename="package://zj_base/meshes/modle.dae" />
        </geometry>
        <origin xyz="0 0 0" rpy="0 0 0" />
        <material name="yellow">
          <color rgba="0.5 0.3 0.0 0.5" />
        </material>
      </visual>
      <collision>
        <geometry>
          <!-- 使用相同的DAE模型作为碰撞体 -->
          <mesh filename="package://zj_base/meshes/modle.dae" />
        </geometry>
        <origin xyz="0 0 0" rpy="0 0 0" />
      </collision>
      <xacro:cylinder_inertial_matrix m="${base_link_m}" r="${base_link_radius}" h="${base_link_length}" />
    </link>

    <joint name="base_link2base_footprint" type="fixed">
      <parent link="base_footprint" />
      <child link="base_link" />
      <origin xyz="0 0 ${earth_space + base_link_length / 2 }" />
    </joint>
    
    <!-- <gazebo reference="base_link">
        <material>Gazebo/Yellow</material>
    </gazebo> -->

    <!-- 驱动轮属性 -->
    <xacro:property name="wheel_radius" value="0.075" />
    <xacro:property name="wheel_length" value="0.03" />
    <xacro:property name="wheel_m" value="0.2" />

    <!-- 驱动轮宏实现 -->
    <xacro:macro name="add_wheels" params="name flag">
      <link name="${name}_wheel">
        <visual>
          <geometry>
            <cylinder radius="${wheel_radius}" length="${wheel_length}" />
          </geometry>
          <origin xyz="0.0 0.0 0.0" rpy="${PI / 2} 0.0 0.0" />
          <material name="black">
            <color rgba="0.0 0.0 0.0 1.0" />
          </material>
        </visual>
        <collision>
          <geometry>
            <cylinder radius="${wheel_radius}" length="${wheel_length}" />
          </geometry>
          <origin xyz="0.0 0.0 0.0" rpy="${PI / 2} 0.0 0.0" />
        </collision>
        <xacro:cylinder_inertial_matrix m="${wheel_m}" r="${wheel_radius}" h="${wheel_length}" />
      </link>

      <joint name="${name}_wheel2base_link" type="continuous">
        <parent link="base_link" />
        <child link="${name}_wheel" />
        <origin xyz="0 ${flag * base_link_radius} ${-(earth_space + base_link_length / 2 - wheel_radius) }" />
        <axis xyz="0 1 0" />
      </joint>

      <gazebo reference="${name}_wheel">
        <material>Gazebo/Black</material>
      </gazebo>
    </xacro:macro>
    
    <xacro:add_wheels name="left" flag="1" />
    <xacro:add_wheels name="right" flag="-1" />

    <!-- 支撑轮属性 -->
    <xacro:property name="support_wheel_radius" value="0.025" />
    <xacro:property name="support_wheel_m" value="0.1" />

    <!-- 支撑轮宏 -->
    <xacro:macro name="add_support_wheel" params="name flag" >
      <link name="${name}_wheel">
        <visual>
            <geometry>
                <sphere radius="${support_wheel_radius}" />
            </geometry>
            <origin xyz="0 0 0" rpy="0 0 0" />
            <material name="black">
            <color rgba="0.0 0.0 0.0 1.0" />
          </material>
        </visual>
        <collision>
            <geometry>
                <sphere radius="${support_wheel_radius}" />
            </geometry>
            <origin xyz="0 0 0" rpy="0 0 0" />
        </collision>
        <xacro:sphere_inertial_matrix m="${support_wheel_m}" r="${support_wheel_radius}" />
      </link>

      <joint name="${name}_wheel2base_link" type="continuous">
          <parent link="base_link" />
          <child link="${name}_wheel" />
          <origin xyz="${flag * (base_link_radius - support_wheel_radius)} 0 ${-(base_link_length / 2 + earth_space / 2)}" />
          <axis xyz="1 0 0" />
      </joint>
      
      <gazebo reference="${name}_wheel">
        <material>Gazebo/Black</material>
        <mu1>0.0</mu1>
        <mu2>0.0</mu2>
        <kp>1000000.0</kp>
        <kd>100.0</kd>
      </gazebo>
    </xacro:macro>

    <xacro:add_support_wheel name="front" flag="1" />
    <xacro:add_support_wheel name="back" flag="-1" />

    <!-- 惯性矩阵宏定义 -->
    <xacro:macro name="cylinder_inertial_matrix" params="m r h">
      <inertial>
        <mass value="${m}" />
        <inertia ixx="${m*(3*r*r+h*h)/12}" ixy="0" ixz="0"
                 iyy="${m*(3*r*r+h*h)/12}" iyz="0"
                 izz="${m*r*r/2}" />
      </inertial>
    </xacro:macro>

    <xacro:macro name="sphere_inertial_matrix" params="m r">
      <inertial>
        <mass value="${m}" />
        <inertia ixx="${2*m*r*r/5}" ixy="0" ixz="0"
                 iyy="${2*m*r*r/5}" iyz="0"
                 izz="${2*m*r*r/5}" />
      </inertial>
    </xacro:macro>

</robot>