<?xml version="1.0" ?>
<!-- =================================================================================== -->
<!-- |    This document was autogenerated by xacro from test.xacro                     | -->
<!-- |    EDITING THIS FILE BY HAND IS NOT RECOMMENDED                                 | -->
<!-- =================================================================================== -->
<!-- 组合小车底盘与摄像头 -->
<robot name="my_car_camera">
  <!-- 质量  -->
  <!-- 底盘 -->
  <link name="base_footprint">
    <visual>
      <geometry>
        <sphere radius="0.001"/>
      </geometry>
    </visual>
  </link>
  <link name="base_link">
    <visual>
      <geometry>
        <mesh filename="/home/zj/graduate_design/src/zj_base/meshes/modle.stl"/>
      </geometry>
      <origin rpy="0 0 0" xyz="0 0 0"/>
      <material name="yellow">
        <color rgba="0.5 0.3 0.0 0.5"/>
      </material>
    </visual>
    <collision>
      <geometry>
        <cylinder length="0.9" radius="0.25"/>
      </geometry>
      <origin rpy="0 0 0" xyz="0 0 0"/>
    </collision>
    <inertial>
      <mass value="5.0"/>
      <inertia ixx="0.4156250000000001" ixy="0" ixz="0" iyy="0.4156250000000001" iyz="0" izz="0.15625"/>
    </inertial>
  </link>
  <joint name="base_link2base_footprint" type="fixed">
    <parent link="base_footprint"/>
    <child link="base_link"/>
    <origin xyz="0 0 0.5"/>
  </joint>
  <gazebo reference="base_link">
    <material>Gazebo/Yellow</material>
  </gazebo>
  <!-- 质量  -->
  <link name="left_wheel">
    <visual>
      <geometry>
        <cylinder length="0.03" radius="0.075"/>
      </geometry>
      <origin rpy="1.5707963 0.0 0.0" xyz="0.0 0.0 0.0"/>
      <material name="black">
        <color rgba="0.0 0.0 0.0 1.0"/>
      </material>
    </visual>
    <collision>
      <geometry>
        <cylinder length="0.03" radius="0.075"/>
      </geometry>
      <origin rpy="1.5707963 0.0 0.0" xyz="0.0 0.0 0.0"/>
    </collision>
    <inertial>
      <mass value="0.2"/>
      <inertia ixx="0.00029625" ixy="0" ixz="0" iyy="0.00029625" iyz="0" izz="0.0005625"/>
    </inertial>
  </link>
  <joint name="left_wheel2base_link" type="continuous">
    <parent link="base_link"/>
    <child link="left_wheel"/>
    <origin xyz="0 0.25 -0.425"/>
    <axis xyz="0 1 0"/>
  </joint>
  <gazebo reference="left_wheel">
    <material>Gazebo/Black</material>
  </gazebo>
  <link name="right_wheel">
    <visual>
      <geometry>
        <cylinder length="0.03" radius="0.075"/>
      </geometry>
      <origin rpy="1.5707963 0.0 0.0" xyz="0.0 0.0 0.0"/>
      <material name="black">
        <color rgba="0.0 0.0 0.0 1.0"/>
      </material>
    </visual>
    <collision>
      <geometry>
        <cylinder length="0.03" radius="0.075"/>
      </geometry>
      <origin rpy="1.5707963 0.0 0.0" xyz="0.0 0.0 0.0"/>
    </collision>
    <inertial>
      <mass value="0.2"/>
      <inertia ixx="0.00029625" ixy="0" ixz="0" iyy="0.00029625" iyz="0" izz="0.0005625"/>
    </inertial>
  </link>
  <joint name="right_wheel2base_link" type="continuous">
    <parent link="base_link"/>
    <child link="right_wheel"/>
    <origin xyz="0 -0.25 -0.425"/>
    <axis xyz="0 1 0"/>
  </joint>
  <gazebo reference="right_wheel">
    <material>Gazebo/Black</material>
  </gazebo>
  <!-- 质量  -->
  <link name="front_wheel">
    <visual>
      <geometry>
        <sphere radius="0.025"/>
      </geometry>
      <origin rpy="0 0 0" xyz="0 0 0"/>
      <material name="black">
        <color rgba="0.0 0.0 0.0 1.0"/>
      </material>
    </visual>
    <collision>
      <geometry>
        <sphere radius="0.025"/>
      </geometry>
      <origin rpy="0 0 0" xyz="0 0 0"/>
    </collision>
    <inertial>
      <mass value="0.1"/>
      <inertia ixx="2.5000000000000005e-05" ixy="0" ixz="0" iyy="2.5000000000000005e-05" iyz="0" izz="2.5000000000000005e-05"/>
    </inertial>
  </link>
  <joint name="front_wheel2base_link" type="continuous">
    <parent link="base_link"/>
    <child link="front_wheel"/>
    <origin xyz="0.225 0 -0.47500000000000003"/>
    <axis xyz="1 0 0"/>
  </joint>
  <gazebo reference="front_wheel">
    <material>Gazebo/Black</material>
    <mu1>0.0</mu1>
    <!-- 滚动摩擦 -->
    <mu2>0.0</mu2>
    <!-- 滑动摩擦 -->
    <kp>1000000.0</kp>
    <kd>100.0</kd>
  </gazebo>
  <link name="back_wheel">
    <visual>
      <geometry>
        <sphere radius="0.025"/>
      </geometry>
      <origin rpy="0 0 0" xyz="0 0 0"/>
      <material name="black">
        <color rgba="0.0 0.0 0.0 1.0"/>
      </material>
    </visual>
    <collision>
      <geometry>
        <sphere radius="0.025"/>
      </geometry>
      <origin rpy="0 0 0" xyz="0 0 0"/>
    </collision>
    <inertial>
      <mass value="0.1"/>
      <inertia ixx="2.5000000000000005e-05" ixy="0" ixz="0" iyy="2.5000000000000005e-05" iyz="0" izz="2.5000000000000005e-05"/>
    </inertial>
  </link>
  <joint name="back_wheel2base_link" type="continuous">
    <parent link="base_link"/>
    <child link="back_wheel"/>
    <origin xyz="-0.225 0 -0.47500000000000003"/>
    <axis xyz="1 0 0"/>
  </joint>
  <gazebo reference="back_wheel">
    <material>Gazebo/Black</material>
    <mu1>0.0</mu1>
    <!-- 滚动摩擦 -->
    <mu2>0.0</mu2>
    <!-- 滑动摩擦 -->
    <kp>1000000.0</kp>
    <kd>100.0</kd>
  </gazebo>
  <transmission name="left_wheel2base_link_trans">
    <type>transmission_interface/SimpleTransmission</type>
    <joint name="left_wheel2base_link">
      <hardwareInterface>hardware_interface/VelocityJointInterface</hardwareInterface>
    </joint>
    <actuator name="left_wheel2base_link_motor">
      <hardwareInterface>hardware_interface/VelocityJointInterface</hardwareInterface>
      <mechanicalReduction>1</mechanicalReduction>
    </actuator>
  </transmission>
  <transmission name="right_wheel2base_link_trans">
    <type>transmission_interface/SimpleTransmission</type>
    <joint name="right_wheel2base_link">
      <hardwareInterface>hardware_interface/VelocityJointInterface</hardwareInterface>
    </joint>
    <actuator name="right_wheel2base_link_motor">
      <hardwareInterface>hardware_interface/VelocityJointInterface</hardwareInterface>
      <mechanicalReduction>1</mechanicalReduction>
    </actuator>
  </transmission>
  <!-- Gazebo ROS Control 插件 -->
  <gazebo>
    <plugin filename="libgazebo_ros_control.so" name="gazebo_ros_control">
      <robotNamespace>/</robotNamespace>
      <robotSimType>gazebo_ros_control/DefaultRobotHWSim</robotSimType>
      <controlPeriod>0.001</controlPeriod>
    </plugin>
  </gazebo>
  <!-- 支架安装的z坐标:底盘高度 / 2 + 支架高度 / 2  -->
  <link name="suport">
    <visual>
      <geometry>
        <cylinder length="0.05" radius="0.01"/>
      </geometry>
      <origin rpy="0 0 0" xyz="0.0 0.0 0.0"/>
      <material name="grey">
        <color rgba="0.5 0.5 0.5 1.0"/>
      </material>
    </visual>
    <collision>
      <geometry>
        <cylinder length="0.05" radius="0.01"/>
      </geometry>
      <origin rpy="0 0 0" xyz="0.0 0.0 0.0"/>
    </collision>
    <inertial>
      <origin xyz="0 0 0"/>
      <mass value="0.1"/>
      <inertia ixx="0.0001" ixy="0" ixz="0" iyy="0.0001" iyz="0" izz="0.0001"/>
    </inertial>
  </link>
  <joint name="support2base_link" type="fixed">
    <parent link="base_link"/>
    <child link="suport"/>
    <origin rpy="0 0 0" xyz="0 0 0.47500000000000003"/>
  </joint>
  <link name="laser">
    <visual>
      <geometry>
        <cylinder length="0.02" radius="0.05"/>
      </geometry>
      <origin rpy="0 0 0" xyz="0 0 0"/>
      <material name="black">
        <color rgba="0.0 0.0 0.0 1.0"/>
      </material>
    </visual>
    <collision>
      <geometry>
        <cylinder length="0.02" radius="0.05"/>
      </geometry>
      <origin rpy="0 0 0" xyz="0 0 0"/>
    </collision>
    <inertial>
      <origin xyz="0 0 0"/>
      <mass value="0.2"/>
      <inertia ixx="0.0001" ixy="0" ixz="0" iyy="0.0001" iyz="0" izz="0.0001"/>
    </inertial>
  </link>
  <joint name="laser2support" type="fixed">
    <parent link="suport"/>
    <child link="laser"/>
    <origin rpy="0 0 0" xyz="0 0 0.035"/>
  </joint>
  <!-- 雷达 -->
  <gazebo reference="laser">
    <sensor name="rplidar" type="ray">
      <pose>0 0 0 0 0 0</pose>
      <visualize>false</visualize>
      <update_rate>5.5</update_rate>
      <ray>
        <scan>
          <horizontal>
            <samples>360</samples>
            <resolution>1</resolution>
            <min_angle>-3.14159</min_angle>
            <max_angle>3.14159</max_angle>
          </horizontal>
        </scan>
        <range>
          <min>0.10</min>
          <max>30.0</max>
          <resolution>0.01</resolution>
        </range>
        <noise>
          <type>gaussian</type>
          <mean>0.0</mean>
          <stddev>0.01</stddev>
        </noise>
      </ray>
      <plugin filename="libgazebo_ros_laser.so" name="gazebo_rplidar">
        <topicName>/scan</topicName>
        <frameName>laser</frameName>
      </plugin>
    </sensor>
  </gazebo>
  <link name="camera">
    <visual>
      <geometry>
        <box size="0.03 0.02 0.03"/>
      </geometry>
      <origin rpy="0 0 1.5705" xyz="0 0 0"/>
      <material name="black">
        <color rgba="0.0 0.0 0.0 1.0"/>
      </material>
    </visual>
    <collision>
      <geometry>
        <box size="0.03 0.02 0.03"/>
      </geometry>
      <origin rpy="0 0 1.5705" xyz="0 0 0"/>
    </collision>
    <inertial>
      <origin xyz="0 0 0"/>
      <mass value="0.1"/>
      <inertia ixx="0.0001" ixy="0" ixz="0" iyy="0.0001" iyz="0" izz="0.0001"/>
    </inertial>
  </link>
  <joint name="camera2base_link" type="fixed">
    <parent link="base_link"/>
    <child link="camera"/>
    <origin rpy="0 0 0" xyz="0.23 0.0 0.465"/>
  </joint>
  <gazebo reference="camera">
    <material>Gazebo/Black</material>
  </gazebo>
  <!-- 被引用的link -->
  <gazebo reference="camera">
    <!-- 类型设置为 camara -->
    <sensor name="camera_node" type="camera">
      <update_rate>30.0</update_rate>
      <!-- 更新频率 -->
      <!-- 摄像头基本信息设置 -->
      <camera name="head">
        <horizontal_fov>1.3962634</horizontal_fov>
        <image>
          <width>1280</width>
          <height>720</height>
          <format>R8G8B8</format>
        </image>
        <clip>
          <near>0.02</near>
          <far>300</far>
        </clip>
        <noise>
          <type>gaussian</type>
          <mean>0.0</mean>
          <stddev>0.007</stddev>
        </noise>
      </camera>
      <!-- 核心插件 -->
      <plugin filename="libgazebo_ros_camera.so" name="gazebo_camera">
        <alwaysOn>true</alwaysOn>
        <updateRate>0.0</updateRate>
        <cameraName>/camera</cameraName>
        <imageTopicName>image_raw</imageTopicName>
        <cameraInfoTopicName>camera_info</cameraInfoTopicName>
        <frameName>camera</frameName>
        <hackBaseline>0.07</hackBaseline>
        <distortionK1>0.0</distortionK1>
        <distortionK2>0.0</distortionK2>
        <distortionK3>0.0</distortionK3>
        <distortionT1>0.0</distortionT1>
        <distortionT2>0.0</distortionT2>
      </plugin>
    </sensor>
  </gazebo>
  <gazebo reference="kinect link名称">
    <sensor name="camera" type="depth">
      <always_on>true</always_on>
      <update_rate>20.0</update_rate>
      <camera>
        <horizontal_fov>1.0470000000000002</horizontal_fov>
        <image>
          <format>R8G8B8</format>
          <width>640</width>
          <height>480</height>
        </image>
        <clip>
          <near>0.05</near>
          <far>8.0</far>
        </clip>
      </camera>
      <plugin filename="libgazebo_ros_openni_kinect.so" name="kinect_camera_controller">
        <cameraName>camera</cameraName>
        <alwaysOn>true</alwaysOn>
        <updateRate>10</updateRate>
        <imageTopicName>rgb/image_raw</imageTopicName>
        <depthImageTopicName>depth/image_raw</depthImageTopicName>
        <pointCloudTopicName>depth/points</pointCloudTopicName>
        <cameraInfoTopicName>rgb/camera_info</cameraInfoTopicName>
        <depthImageCameraInfoTopicName>depth/camera_info</depthImageCameraInfoTopicName>
        <frameName>kinect link名称</frameName>
        <baseline>0.1</baseline>
        <distortion_k1>0.0</distortion_k1>
        <distortion_k2>0.0</distortion_k2>
        <distortion_k3>0.0</distortion_k3>
        <distortion_t1>0.0</distortion_t1>
        <distortion_t2>0.0</distortion_t2>
        <pointCloudCutoff>0.4</pointCloudCutoff>
      </plugin>
    </sensor>
  </gazebo>
  <!-- 抽屉组件1 - 只优化物理参数，保持位置不变 -->
  <link name="drawer">
    <visual>
      <geometry>
        <mesh filename="package://zj_base/meshes/box.stl"/>
      </geometry>
      <origin rpy="0 0 0" xyz="0 0 0"/>
      <material name="drawer_material">
        <color rgba="0.8 0.8 0.8 1.0"/>
      </material>
    </visual>
    <collision>
      <geometry>
        <!-- <box size="0.1 0.15 0.05"/> -->
        <mesh filename="package://zj_base/meshes/box.stl"/>
      </geometry>
      <origin rpy="0 0 0" xyz="0 0 0"/>
      <surface>
        <friction>
          <ode>
            <mu>0.3</mu>
            <!-- 大幅降低摩擦 -->
            <mu2>0.1</mu2>
            <!-- 大幅降低摩擦 -->
          </ode>
        </friction>
      </surface>
    </collision>
    <inertial>
      <origin xyz="0 0 0"/>
      <mass value="0.5"/>
      <!-- 减轻质量 -->
      <inertia ixx="0.0001" ixy="0" ixz="0" iyy="0.0001" iyz="0" izz="0.0001"/>
      <!-- 减小惯性 -->
    </inertial>
  </link>
  <joint name="drawer2base_link" type="prismatic">
    <parent link="base_link"/>
    <child link="drawer"/>
    <origin rpy="0 0 0" xyz="0 0 0"/>
    <!-- 保持位置不变 -->
    <axis xyz="1 0 0"/>
    <limit effort="500" lower="0" upper="0.2" velocity="2.0"/>
    <!-- 只增加effort -->
    <dynamics damping="0.01" friction="0.0"/>
    <!-- 大幅减少阻尼和摩擦 -->
  </joint>
  <gazebo reference="drawer">
    <material>Gazebo/Grey</material>
    <mu1>0.3</mu1>
    <!-- 降低Gazebo摩擦 -->
    <mu2>0.1</mu2>
    <!-- 降低Gazebo摩擦 -->
    <kp>100000.0</kp>
    <!-- 降低接触刚度 -->
    <kd>100.0</kd>
    <!-- 降低接触阻尼 -->
  </gazebo>
  <gazebo reference="drawer2base_link">
    <stopCfm>0.0</stopCfm>
    <stopErp>0.2</stopErp>
    <!-- 降低ERP -->
    <provideFeedback>true</provideFeedback>
    <physics>
      <ode>
        <limit>
          <cfm>0.0</cfm>
          <erp>0.2</erp>
          <!-- 降低ERP -->
        </limit>
        <fdir1>1 0 0</fdir1>
        <friction>1.0 0.5 0.0</friction>
        <!-- 大幅降低摩擦 -->
        <suspension>
          <cfm>0.0</cfm>
          <erp>0.2</erp>
          <!-- 降低ERP -->
        </suspension>
      </ode>
    </physics>
  </gazebo>
  <!-- 抽屉组件2 - 同样只优化物理参数 -->
  <link name="drawer2">
    <visual>
      <geometry>
        <mesh filename="package://zj_base/meshes/box2.stl"/>
      </geometry>
      <origin rpy="0 0 0" xyz="0 0 0"/>
      <material name="drawer_material">
        <color rgba="0.8 0.8 0.8 1.0"/>
      </material>
    </visual>
    <collision>
      <geometry>
        <box size="0.1 0.15 0.05"/>
      </geometry>
      <origin rpy="0 0 0" xyz="0 0 0"/>
      <surface>
        <friction>
          <ode>
            <mu>0.3</mu>
            <mu2>0.1</mu2>
          </ode>
        </friction>
      </surface>
    </collision>
    <inertial>
      <origin xyz="0 0 0"/>
      <mass value="0.5"/>
      <inertia ixx="0.0001" ixy="0" ixz="0" iyy="0.0001" iyz="0" izz="0.0001"/>
    </inertial>
  </link>
  <joint name="drawer22base_link" type="prismatic">
    <parent link="base_link"/>
    <child link="drawer2"/>
    <origin rpy="0 0 0" xyz="0 0 0"/>
    <!-- 保持位置不变 -->
    <axis xyz="1 0 0"/>
    <limit effort="500" lower="0" upper="0.2" velocity="2.0"/>
    <dynamics damping="0.01" friction="0.0"/>
  </joint>
  <gazebo reference="drawer2">
    <material>Gazebo/Grey</material>
    <mu1>0.3</mu1>
    <mu2>0.1</mu2>
    <kp>100000.0</kp>
    <kd>100.0</kd>
  </gazebo>
  <gazebo reference="drawer22base_link">
    <stopCfm>0.0</stopCfm>
    <stopErp>0.2</stopErp>
    <provideFeedback>true</provideFeedback>
    <physics>
      <ode>
        <limit>
          <cfm>0.0</cfm>
          <erp>0.2</erp>
        </limit>
        <fdir1>1 0 0</fdir1>
        <friction>1.0 0.5 0.0</friction>
        <suspension>
          <cfm>0.0</cfm>
          <erp>0.2</erp>
        </suspension>
      </ode>
    </physics>
  </gazebo>
  <!-- 抽屉组件3 - 同样只优化物理参数 -->
  <link name="drawer3">
    <visual>
      <geometry>
        <mesh filename="package://zj_base/meshes/box3.stl"/>
      </geometry>
      <origin rpy="0 0 0" xyz="0 0 0"/>
      <material name="drawer_material">
        <color rgba="0.8 0.8 0.8 1.0"/>
      </material>
    </visual>
    <collision>
      <geometry>
        <box size="0.1 0.15 0.05"/>
      </geometry>
      <origin rpy="0 0 0" xyz="0 0 0"/>
      <surface>
        <friction>
          <ode>
            <mu>0.3</mu>
            <mu2>0.1</mu2>
          </ode>
        </friction>
      </surface>
    </collision>
    <inertial>
      <origin xyz="0 0 0"/>
      <mass value="0.5"/>
      <inertia ixx="0.0001" ixy="0" ixz="0" iyy="0.0001" iyz="0" izz="0.0001"/>
    </inertial>
  </link>
  <joint name="drawer32base_link" type="prismatic">
    <parent link="base_link"/>
    <child link="drawer3"/>
    <origin rpy="0 0 0" xyz="0 0 0"/>
    <!-- 保持位置不变 -->
    <axis xyz="1 0 0"/>
    <limit effort="500" lower="0" upper="0.2" velocity="2.0"/>
    <dynamics damping="0.01" friction="0.0"/>
  </joint>
  <gazebo reference="drawer3">
    <material>Gazebo/Grey</material>
    <mu1>0.3</mu1>
    <mu2>0.1</mu2>
    <kp>100000.0</kp>
    <kd>100.0</kd>
  </gazebo>
  <gazebo reference="drawer32base_link">
    <stopCfm>0.0</stopCfm>
    <stopErp>0.2</stopErp>
    <provideFeedback>true</provideFeedback>
    <physics>
      <ode>
        <limit>
          <cfm>0.0</cfm>
          <erp>0.2</erp>
        </limit>
        <fdir1>1 0 0</fdir1>
        <friction>1.0 0.5 0.0</friction>
        <suspension>
          <cfm>0.0</cfm>
          <erp>0.2</erp>
        </suspension>
      </ode>
    </physics>
  </gazebo>
  <!-- Gazebo ROS Control 插件 -->
  <!-- <gazebo>
    <plugin name="gazebo_ros_control" filename="libgazebo_ros_control.so">
      <robotNamespace>/</robotNamespace>
      <robotSimType>gazebo_ros_control/DefaultRobotHWSim</robotSimType>
      <legacyModeNS>true</legacyModeNS>
    </plugin>
  </gazebo> -->
  <!-- 抽屉1位置控制器 -->
  <gazebo>
    <plugin filename="libgazebo_ros_joint_control.so" name="drawer1_controller">
      <jointName>drawer2base_link</jointName>
      <type>position</type>
      <topicName>drawer1/command</topicName>
      <pid>
        <p>800.0</p>
        <i>5.0</i>
        <d>120.0</d>
      </pid>
    </plugin>
  </gazebo>
  <!-- 抽屉2位置控制器 -->
  <gazebo>
    <plugin filename="libgazebo_ros_joint_control.so" name="drawer2_controller">
      <jointName>drawer22base_link</jointName>
      <type>position</type>
      <topicName>drawer2/command</topicName>
      <pid>
        <p>800.0</p>
        <i>5.0</i>
        <d>120.0</d>
      </pid>
    </plugin>
  </gazebo>
  <!-- 抽屉3位置控制器 -->
  <!-- <gazebo>
    <plugin filename="libgazebo_ros_joint_control.so" name="drawer3_controller">
      <jointName>drawer32base_link</jointName>
      <type>position</type>
      <topicName>drawer3/command</topicName>
      <pid>
        <p>800.0</p>
        <i>5.0</i>
        <d>120.0</d>
      </pid>
    </plugin>
  </gazebo> -->
  <transmission name="drawer2base_link_trans">
    <type>transmission_interface/SimpleTransmission</type>
    <joint name="drawer2base_link">
      <hardwareInterface>hardware_interface/EffortJointInterface</hardwareInterface>
    </joint>
    <actuator name="drawer2base_link_motor">
      <hardwareInterface>hardware_interface/EffortJointInterface</hardwareInterface>
      <mechanicalReduction>1</mechanicalReduction>
    </actuator>
  </transmission>
  <transmission name="drawer22base_link_trans">
    <type>transmission_interface/SimpleTransmission</type>
    <joint name="drawer22base_link">
      <hardwareInterface>hardware_interface/EffortJointInterface</hardwareInterface>
    </joint>
    <actuator name="drawer22base_link_motor">
      <hardwareInterface>hardware_interface/EffortJointInterface</hardwareInterface>
      <mechanicalReduction>1</mechanicalReduction>
    </actuator>
  </transmission>
  <transmission name="drawer32base_link_trans">
    <type>transmission_interface/SimpleTransmission</type>
    <joint name="drawer32base_link">
      <hardwareInterface>hardware_interface/EffortJointInterface</hardwareInterface>
    </joint>
    <actuator name="drawer32base_link_motor">
      <hardwareInterface>hardware_interface/EffortJointInterface</hardwareInterface>
      <mechanicalReduction>1</mechanicalReduction>
    </actuator>
  </transmission>
  <!-- Gazebo插件配置 - 如果还没有在其他地方配置的话 -->
  <!-- <gazebo>
    <plugin name="gazebo_ros_control" filename="libgazebo_ros_control.so">
      <robotNamespace>/</robotNamespace>
      <robotSimType>gazebo_ros_control/DefaultRobotHWSim</robotSimType>
      <controlPeriod>0.001</controlPeriod>
    </plugin>
  </gazebo> -->
</robot>

